Workbook

Sheet Summary
A1: Minnesota Specialist Clinics
A2: Every organization registered in the federal NPI Registry (CMS) under these specialties with a Minnesota practice address, its own name and a phone number. Pulled September 24, 2026. TMJ specialists and oral surgeons added October 19, 2026, each one checked on the web.
A4: =COUNTA('All Clinics'!$A:$A)-1 -> 953 | C4: =COUNTIF('All Clinics'!$M:$M,"No") -> 890
A5: clinic locations across Minnesota | C5: of them are not on Xpert Connect yet
A6: ="Plus "&TEXT(COUNTA('Older Entries'!$A:$A)-1,"#,##0")&" older registry entries on the 'Older Entries' sheet: clinics that have not updated their federal registration since before 2022. Call to confirm before using them." -> Plus 2,081 older registry entries on the 'Older Entries' sheet: clinics that have not updated their federal registration since before 2022. Call to confirm before using them.
A8: By specialty group
A9: Group | B9: Clinics | C9: Not on Xpert Connect | D9: Older entries | E9: What it includes
A10: Injury Physicians | B10: =COUNTA('Injury Physicians'!$A:$A)-1 -> 153 | C10: =COUNTIF('Injury Physicians'!$M:$M,"No") -> 96 | D10: =COUNTIF('Older Entries'!$B:$B,"Injury Physicians")+COUNTIF('Older Entries'!$C:$C,"*Injury Physicians*") -> 160 | E10: Orthopedics, spine, sports medicine, neurosurgery, pain, PM&R, neurology
A11: Chiropractic | B11: =COUNTA('Chiropractic'!$A:$A)-1 -> 440 | C11: =COUNTIF('Chiropractic'!$M:$M,"No") -> 439 | D11: =COUNTIF('Older Entries'!$B:$B,"Chiropractic")+COUNTIF('Older Entries'!$C:$C,"*Chiropractic*") -> 1617 | E11: Chiropractic clinics
A12: Physical Therapy | B12: =COUNTA('Physical Therapy'!$A:$A)-1 -> 298 | C12: =COUNTIF('Physical Therapy'!$M:$M,"No") -> 288 | D12: =COUNTIF('Older Entries'!$B:$B,"Physical Therapy")+COUNTIF('Older Entries'!$C:$C,"*Physical Therapy*") -> 298 | E12: Physical therapy clinics
A13: Imaging | B13: =COUNTA(Imaging!$A:$A)-1 -> 16 | C13: =COUNTIF(Imaging!$M:$M,"No") -> 13 | D13: =COUNTIF('Older Entries'!$B:$B,"Imaging")+COUNTIF('Older Entries'!$C:$C,"*Imaging*") -> 43 | E13: Radiology and MRI centers
A14: TMJ Specialists | B14: =COUNTA('TMJ Specialists'!$A:$A)-1 -> 33 | C14: =COUNTIF('TMJ Specialists'!$P:$P,"No") -> 32 | D14: =COUNTIF('Older Entries'!$B:$B,"TMJ Specialists")+COUNTIF('Older Entries'!$C:$C,"*TMJ Specialists*") -> 1 | E14: TMJ and orofacial pain specialists and clinics
A15: Oral Surgery | B15: =COUNTA('Oral Surgery'!$A:$A)-1 -> 67 | C15: =COUNTIF('Oral Surgery'!$Q:$Q,"No") -> 67 | D15: =COUNTIF('Older Entries'!$B:$B,"Oral Surgery")+COUNTIF('Older Entries'!$C:$C,"*Oral Surgery*") -> 10 | E15: Oral and maxillofacial surgeons (TMJ and jaw surgery)
A16: A multi-specialty clinic is listed in each of its groups, so the groups add up to more than the total.
A18: By region (each clinic counted once, under its main specialty group)
A19: Region | B19: Injury Physicians | C19: Chiropractic | D19: Physical Therapy | E19: Imaging | F19: TMJ Specialists | G19: Oral Surgery | H19: Total
A20: Twin Cities Metro | B20: =COUNTIFS('All Clinics'!$I:$I,$A20,'All Clinics'!$B:$B,"Injury Physicians") -> 109 | C20: =COUNTIFS('All Clinics'!$I:$I,$A20,'All Clinics'!$B:$B,"Chiropractic") -> 279 | D20: =COUNTIFS('All Clinics'!$I:$I,$A20,'All Clinics'!$B:$B,"Physical Therapy") -> 166 | E20: =COUNTIFS('All Clinics'!$I:$I,$A20,'All Clinics'!$B:$B,"Imaging") -> 10 | F20: =COUNTIFS('All Clinics'!$I:$I,$A20,'All Clinics'!$B:$B,"TMJ Specialists") -> 27 | G20: =COUNTIFS('All Clinics'!$I:$I,$A20,'All Clinics'!$B:$B,"Oral Surgery") -> 50 | H20: =SUM(B20:G20) -> 641
A21: Central Minnesota | B21: =COUNTIFS('All Clinics'!$I:$I,$A21,'All Clinics'!$B:$B,"Injury Physicians") -> 2 | C21: =COUNTIFS('All Clinics'!$I:$I,$A21,'All Clinics'!$B:$B,"Chiropractic") -> 21 | D21: =COUNTIFS('All Clinics'!$I:$I,$A21,'All Clinics'!$B:$B,"Physical Therapy") -> 11 | E21: =COUNTIFS('All Clinics'!$I:$I,$A21,'All Clinics'!$B:$B,"Imaging") -> 0 | F21: =COUNTIFS('All Clinics'!$I:$I,$A21,'All Clinics'!$B:$B,"TMJ Specialists") -> 1 | G21: =COUNTIFS('All Clinics'!$I:$I,$A21,'All Clinics'!$B:$B,"Oral Surgery") -> 2 | H21: =SUM(B21:G21) -> 37
A22: Northeast Minnesota | B22: =COUNTIFS('All Clinics'!$I:$I,$A22,'All Clinics'!$B:$B,"Injury Physicians") -> 10 | C22: =COUNTIFS('All Clinics'!$I:$I,$A22,'All Clinics'!$B:$B,"Chiropractic") -> 39 | D22: =COUNTIFS('All Clinics'!$I:$I,$A22,'All Clinics'!$B:$B,"Physical Therapy") -> 27 | E22: =COUNTIFS('All Clinics'!$I:$I,$A22,'All Clinics'!$B:$B,"Imaging") -> 0 | F22: =COUNTIFS('All Clinics'!$I:$I,$A22,'All Clinics'!$B:$B,"TMJ Specialists") -> 0 | G22: =COUNTIFS('All Clinics'!$I:$I,$A22,'All Clinics'!$B:$B,"Oral Surgery") -> 6 | H22: =SUM(B22:G22) -> 82
A23: Northwest Minnesota | B23: =COUNTIFS('All Clinics'!$I:$I,$A23,'All Clinics'!$B:$B,"Injury Physicians") -> 2 | C23: =COUNTIFS('All Clinics'!$I:$I,$A23,'All Clinics'!$B:$B,"Chiropractic") -> 7 | D23: =COUNTIFS('All Clinics'!$I:$I,$A23,'All Clinics'!$B:$B,"Physical Therapy") -> 6 | E23: =COUNTIFS('All Clinics'!$I:$I,$A23,'All Clinics'!$B:$B,"Imaging") -> 0 | F23: =COUNTIFS('All Clinics'!$I:$I,$A23,'All Clinics'!$B:$B,"TMJ Specialists") -> 0 | G23: =COUNTIFS('All Clinics'!$I:$I,$A23,'All Clinics'!$B:$B,"Oral Surgery") -> 0 | H23: =SUM(B23:G23) -> 15
A24: West Central Minnesota | B24: =COUNTIFS('All Clinics'!$I:$I,$A24,'All Clinics'!$B:$B,"Injury Physicians") -> 6 | C24: =COUNTIFS('All Clinics'!$I:$I,$A24,'All Clinics'!$B:$B,"Chiropractic") -> 18 | D24: =COUNTIFS('All Clinics'!$I:$I,$A24,'All Clinics'!$B:$B,"Physical Therapy") -> 16 | E24: =COUNTIFS('All Clinics'!$I:$I,$A24,'All Clinics'!$B:$B,"Imaging") -> 1 | F24: =COUNTIFS('All Clinics'!$I:$I,$A24,'All Clinics'!$B:$B,"TMJ Specialists") -> 1 | G24: =COUNTIFS('All Clinics'!$I:$I,$A24,'All Clinics'!$B:$B,"Oral Surgery") -> 3 | H24: =SUM(B24:G24) -> 45
A25: South Central Minnesota | B25: =COUNTIFS('All Clinics'!$I:$I,$A25,'All Clinics'!$B:$B,"Injury Physicians") -> 7 | C25: =COUNTIFS('All Clinics'!$I:$I,$A25,'All Clinics'!$B:$B,"Chiropractic") -> 23 | D25: =COUNTIFS('All Clinics'!$I:$I,$A25,'All Clinics'!$B:$B,"Physical Therapy") -> 6 | E25: =COUNTIFS('All Clinics'!$I:$I,$A25,'All Clinics'!$B:$B,"Imaging") -> 0 | F25: =COUNTIFS('All Clinics'!$I:$I,$A25,'All Clinics'!$B:$B,"TMJ Specialists") -> 1 | G25: =COUNTIFS('All Clinics'!$I:$I,$A25,'All Clinics'!$B:$B,"Oral Surgery") -> 1 | H25: =SUM(B25:G25) -> 38
A26: Southeast Minnesota | B26: =COUNTIFS('All Clinics'!$I:$I,$A26,'All Clinics'!$B:$B,"Injury Physicians") -> 7 | C26: =COUNTIFS('All Clinics'!$I:$I,$A26,'All Clinics'!$B:$B,"Chiropractic") -> 28 | D26: =COUNTIFS('All Clinics'!$I:$I,$A26,'All Clinics'!$B:$B,"Physical Therapy") -> 23 | E26: =COUNTIFS('All Clinics'!$I:$I,$A26,'All Clinics'!$B:$B,"Imaging") -> 0 | F26: =COUNTIFS('All Clinics'!$I:$I,$A26,'All Clinics'!$B:$B,"TMJ Specialists") -> 3 | G26: =COUNTIFS('All Clinics'!$I:$I,$A26,'All Clinics'!$B:$B,"Oral Surgery") -> 2 | H26: =SUM(B26:G26) -> 63
A27: Southwest Minnesota | B27: =COUNTIFS('All Clinics'!$I:$I,$A27,'All Clinics'!$B:$B,"Injury Physicians") -> 8 | C27: =COUNTIFS('All Clinics'!$I:$I,$A27,'All Clinics'!$B:$B,"Chiropractic") -> 16 | D27: =COUNTIFS('All Clinics'!$I:$I,$A27,'All Clinics'!$B:$B,"Physical Therapy") -> 7 | E27: =COUNTIFS('All Clinics'!$I:$I,$A27,'All Clinics'!$B:$B,"Imaging") -> 0 | F27: =COUNTIFS('All Clinics'!$I:$I,$A27,'All Clinics'!$B:$B,"TMJ Specialists") -> 0 | G27: =COUNTIFS('All Clinics'!$I:$I,$A27,'All Clinics'!$B:$B,"Oral Surgery") -> 1 | H27: =SUM(B27:G27) -> 32
A28: Total | B28: =SUM(B20:B27) -> 151 | C28: =SUM(C20:C27) -> 431 | D28: =SUM(D20:D27) -> 262 | E28: =SUM(E20:E27) -> 11 | F28: =SUM(F20:F27) -> 33 | G28: =SUM(G20:G27) -> 65 | H28: =SUM(H20:H27) -> 953
A30: By county (all 87 Minnesota counties)
A31: County | B31: Region | C31: Injury Physicians | D31: Chiropractic | E31: Physical Therapy | F31: Imaging | G31: TMJ Specialists | H31: Oral Surgery | I31: Total | J31: Older entries
A32: Hennepin | B32: Twin Cities Metro | C32: =COUNTIFS('All Clinics'!$H:$H,$A32,'All Clinics'!$B:$B,"Injury Physicians") -> 50 | D32: =COUNTIFS('All Clinics'!$H:$H,$A32,'All Clinics'!$B:$B,"Chiropractic") -> 108 | E32: =COUNTIFS('All Clinics'!$H:$H,$A32,'All Clinics'!$B:$B,"Physical Therapy") -> 68 | F32: =COUNTIFS('All Clinics'!$H:$H,$A32,'All Clinics'!$B:$B,"Imaging") -> 6 | G32: =COUNTIFS('All Clinics'!$H:$H,$A32,'All Clinics'!$B:$B,"TMJ Specialists") -> 11 | H32: =COUNTIFS('All Clinics'!$H:$H,$A32,'All Clinics'!$B:$B,"Oral Surgery") -> 16 | I32: =SUM(C32:H32) -> 259 | J32: =COUNTIF('Older Entries'!$H:$H,$A32) -> 630
A33: Ramsey | B33: Twin Cities Metro | C33: =COUNTIFS('All Clinics'!$H:$H,$A33,'All Clinics'!$B:$B,"Injury Physicians") -> 22 | D33: =COUNTIFS('All Clinics'!$H:$H,$A33,'All Clinics'!$B:$B,"Chiropractic") -> 39 | E33: =COUNTIFS('All Clinics'!$H:$H,$A33,'All Clinics'!$B:$B,"Physical Therapy") -> 23 | F33: =COUNTIFS('All Clinics'!$H:$H,$A33,'All Clinics'!$B:$B,"Imaging") -> 3 | G33: =COUNTIFS('All Clinics'!$H:$H,$A33,'All Clinics'!$B:$B,"TMJ Specialists") -> 4 | H33: =COUNTIFS('All Clinics'!$H:$H,$A33,'All Clinics'!$B:$B,"Oral Surgery") -> 8 | I33: =SUM(C33:H33) -> 99 | J33: =COUNTIF('Older Entries'!$H:$H,$A33) -> 252
A34: Dakota | B34: Twin Cities Metro | C34: =COUNTIFS('All Clinics'!$H:$H,$A34,'All Clinics'!$B:$B,"Injury Physicians") -> 10 | D34: =COUNTIFS('All Clinics'!$H:$H,$A34,'All Clinics'!$B:$B,"Chiropractic") -> 45 | E34: =COUNTIFS('All Clinics'!$H:$H,$A34,'All Clinics'!$B:$B,"Physical Therapy") -> 27 | F34: =COUNTIFS('All Clinics'!$H:$H,$A34,'All Clinics'!$B:$B,"Imaging") -> 0 | G34: =COUNTIFS('All Clinics'!$H:$H,$A34,'All Clinics'!$B:$B,"TMJ Specialists") -> 2 | H34: =COUNTIFS('All Clinics'!$H:$H,$A34,'All Clinics'!$B:$B,"Oral Surgery") -> 7 | I34: =SUM(C34:H34) -> 91 | J34: =COUNTIF('Older Entries'!$H:$H,$A34) -> 159
A35: Washington | B35: Twin Cities Metro | C35: =COUNTIFS('All Clinics'!$H:$H,$A35,'All Clinics'!$B:$B,"Injury Physicians") -> 10 | D35: =COUNTIFS('All Clinics'!$H:$H,$A35,'All Clinics'!$B:$B,"Chiropractic") -> 25 | E35: =COUNTIFS('All Clinics'!$H:$H,$A35,'All Clinics'!$B:$B,"Physical Therapy") -> 15 | F35: =COUNTIFS('All Clinics'!$H:$H,$A35,'All Clinics'!$B:$B,"Imaging") -> 0 | G35: =COUNTIFS('All Clinics'!$H:$H,$A35,'All Clinics'!$B:$B,"TMJ Specialists") -> 5 | H35: =COUNTIFS('All Clinics'!$H:$H,$A35,'All Clinics'!$B:$B,"Oral Surgery") -> 6 | I35: =SUM(C35:H35) -> 61 | J35: =COUNTIF('Older Entries'!$H:$H,$A35) -> 112
A36: Anoka | B36: Twin Cities Metro | C36: =COUNTIFS('All Clinics'!$H:$H,$A36,'All Clinics'!$B:$B,"Injury Physicians") -> 8 | D36: =COUNTIFS('All Clinics'!$H:$H,$A36,'All Clinics'!$B:$B,"Chiropractic") -> 22 | E36: =COUNTIFS('All Clinics'!$H:$H,$A36,'All Clinics'!$B:$B,"Physical Therapy") -> 13 | F36: =COUNTIFS('All Clinics'!$H:$H,$A36,'All Clinics'!$B:$B,"Imaging") -> 0 | G36: =COUNTIFS('All Clinics'!$H:$H,$A36,'All Clinics'!$B:$B,"TMJ Specialists") -> 1 | H36: =COUNTIFS('All Clinics'!$H:$H,$A36,'All Clinics'!$B:$B,"Oral Surgery") -> 6 | I36: =SUM(C36:H36) -> 50 | J36: =COUNTIF('Older Entries'!$H:$H,$A36) -> 88
A37: St. Louis | B37: Northeast Minnesota | C37: =COUNTIFS('All Clinics'!$H:$H,$A37,'All Clinics'!$B:$B,"Injury Physicians") -> 7 | D37: =COUNTIFS('All Clinics'!$H:$H,$A37,'All Clinics'!$B:$B,"Chiropractic") -> 9 | E37: =COUNTIFS('All Clinics'!$H:$H,$A37,'All Clinics'!$B:$B,"Physical Therapy") -> 14 | F37: =COUNTIFS('All Clinics'!$H:$H,$A37,'All Clinics'!$B:$B,"Imaging") -> 0 | G37: =COUNTIFS('All Clinics'!$H:$H,$A37,'All Clinics'!$B:$B,"TMJ Specialists") -> 0 | H37: =COUNTIFS('All Clinics'!$H:$H,$A37,'All Clinics'!$B:$B,"Oral Surgery") -> 4 | I37: =SUM(C37:H37) -> 34 | J37: =COUNTIF('Older Entries'!$H:$H,$A37) -> 54
A38: Olmsted | B38: Southeast Minnesota | C38: =COUNTIFS('All Clinics'!$H:$H,$A38,'All Clinics'!$B:$B,"Injury Physicians") -> 4 | D38: =COUNTIFS('All Clinics'!$H:$H,$A38,'All Clinics'!$B:$B,"Chiropractic") -> 9 | E38: =COUNTIFS('All Clinics'!$H:$H,$A38,'All Clinics'!$B:$B,"Physical Therapy") -> 9 | F38: =COUNTIFS('All Clinics'!$H:$H,$A38,'All Clinics'!$B:$B,"Imaging") -> 0 | G38: =COUNTIFS('All Clinics'!$H:$H,$A38,'All Clinics'!$B:$B,"TMJ Specialists") -> 3 | H38: =COUNTIFS('All Clinics'!$H:$H,$A38,'All Clinics'!$B:$B,"Oral Surgery") -> 2 | I38: =SUM(C38:H38) -> 27 | J38: =COUNTIF('Older Entries'!$H:$H,$A38) -> 35
A39: Wright | B39: Twin Cities Metro | C39: =COUNTIFS('All Clinics'!$H:$H,$A39,'All Clinics'!$B:$B,"Injury Physicians") -> 1 | D39: =COUNTIFS('All Clinics'!$H:$H,$A39,'All Clinics'!$B:$B,"Chiropractic") -> 12 | E39: =COUNTIFS('All Clinics'!$H:$H,$A39,'All Clinics'!$B:$B,"Physical Therapy") -> 8 | F39: =COUNTIFS('All Clinics'!$H:$H,$A39,'All Clinics'!$B:$B,"Imaging") -> 0 | G39: =COUNTIFS('All Clinics'!$H:$H,$A39,'All Clinics'!$B:$B,"TMJ Specialists") -> 2 | H39: =COUNTIFS('All Clinics'!$H:$H,$A39,'All Clinics'!$B:$B,"Oral Surgery") -> 2 | I39: =SUM(C39:H39) -> 25 | J39: =COUNTIF('Older Entries'!$H:$H,$A39) -> 49
A40: Stearns | B40: Central Minnesota | C40: =COUNTIFS('All Clinics'!$H:$H,$A40,'All Clinics'!$B:$B,"Injury Physicians") -> 2 | D40: =COUNTIFS('All Clinics'!$H:$H,$A40,'All Clinics'!$B:$B,"Chiropractic") -> 8 | E40: =COUNTIFS('All Clinics'!$H:$H,$A40,'All Clinics'!$B:$B,"Physical Therapy") -> 8 | F40: =COUNTIFS('All Clinics'!$H:$H,$A40,'All Clinics'!$B:$B,"Imaging") -> 0 | G40: =COUNTIFS('All Clinics'!$H:$H,$A40,'All Clinics'!$B:$B,"TMJ Specialists") -> 1 | H40: =COUNTIFS('All Clinics'!$H:$H,$A40,'All Clinics'!$B:$B,"Oral Surgery") -> 2 | I40: =SUM(C40:H40) -> 21 | J40: =COUNTIF('Older Entries'!$H:$H,$A40) -> 73
A41: Douglas | B41: West Central Minnesota | C41: =COUNTIFS('All Clinics'!$H:$H,$A41,'All Clinics'!$B:$B,"Injury Physicians") -> 5 | D41: =COUNTIFS('All Clinics'!$H:$H,$A41,'All Clinics'!$B:$B,"Chiropractic") -> 6 | E41: =COUNTIFS('All Clinics'!$H:$H,$A41,'All Clinics'!$B:$B,"Physical Therapy") -> 7 | F41: =COUNTIFS('All Clinics'!$H:$H,$A41,'All Clinics'!$B:$B,"Imaging") -> 1 | G41: =COUNTIFS('All Clinics'!$H:$H,$A41,'All Clinics'!$B:$B,"TMJ Specialists") -> 0 | H41: =COUNTIFS('All Clinics'!$H:$H,$A41,'All Clinics'!$B:$B,"Oral Surgery") -> 1 | I41: =SUM(C41:H41) -> 20 | J41: =COUNTIF('Older Entries'!$H:$H,$A41) -> 16
A42: Carver | B42: Twin Cities Metro | C42: =COUNTIFS('All Clinics'!$H:$H,$A42,'All Clinics'!$B:$B,"Injury Physicians") -> 2 | D42: =COUNTIFS('All Clinics'!$H:$H,$A42,'All Clinics'!$B:$B,"Chiropractic") -> 9 | E42: =COUNTIFS('All Clinics'!$H:$H,$A42,'All Clinics'!$B:$B,"Physical Therapy") -> 5 | F42: =COUNTIFS('All Clinics'!$H:$H,$A42,'All Clinics'!$B:$B,"Imaging") -> 1 | G42: =COUNTIFS('All Clinics'!$H:$H,$A42,'All Clinics'!$B:$B,"TMJ Specialists") -> 0 | H42: =COUNTIFS('All Clinics'!$H:$H,$A42,'All Clinics'!$B:$B,"Oral Surgery") -> 1 | I42: =SUM(C42:H42) -> 18 | J42: =COUNTIF('Older Entries'!$H:$H,$A42) -> 38
A43: Scott | B43: Twin Cities Metro | C43: =COUNTIFS('All Clinics'!$H:$H,$A43,'All Clinics'!$B:$B,"Injury Physicians") -> 1 | D43: =COUNTIFS('All Clinics'!$H:$H,$A43,'All Clinics'!$B:$B,"Chiropractic") -> 9 | E43: =COUNTIFS('All Clinics'!$H:$H,$A43,'All Clinics'!$B:$B,"Physical Therapy") -> 3 | F43: =COUNTIFS('All Clinics'!$H:$H,$A43,'All Clinics'!$B:$B,"Imaging") -> 0 | G43: =COUNTIFS('All Clinics'!$H:$H,$A43,'All Clinics'!$B:$B,"TMJ Specialists") -> 2 | H43: =COUNTIFS('All Clinics'!$H:$H,$A43,'All Clinics'!$B:$B,"Oral Surgery") -> 2 | I43: =SUM(C43:H43) -> 17 | J43: =COUNTIF('Older Entries'!$H:$H,$A43) -> 61
... A118: Wilkin | B118: West Central Minnesota | C118: =COUNTIFS('All Clinics'!$H:$H,$A118,'All Clinics'!$B:$B,"Injury Physicians") -> 0 | D118: =COUNTIFS('All Clinics'!$H:$H,$A118,'All Clinics'!$B:$B,"Chiropractic") -> 0 | E118: =COUNTIFS('All Clinics'!$H:$H,$A118,'All Clinics'!$B:$B,"Physical Therapy") -> 0 | F118: =COUNTIFS('All Clinics'!$H:$H,$A118,'All Clinics'!$B:$B,"Imaging") -> 0 | G118: =COUNTIFS('All Clinics'!$H:$H,$A118,'All Clinics'!$B:$B,"TMJ Specialists") -> 0 | H118: =COUNTIFS('All Clinics'!$H:$H,$A118,'All Clinics'!$B:$B,"Oral Surgery") -> 0 | I118: =SUM(C118:H118) -> 0 | J118: =COUNTIF('Older Entries'!$H:$H,$A118) -> 2

Sheet All Clinics
A1: Clinic Name | B1: Specialty Group | C1: Also In | D1: Specialties | E1: Street | F1: Suite | G1: City | H1: County | I1: Region | J1: ZIP | K1: Phone | L1: Providers at Address | M1: On Xpert Connect | N1: Registry Updated | O1: Legal Name | P1: NPI | Q1: Map | R1: NPPES Record
A2: Health and Healing Family Chiropractic | B2: Chiropractic | D2: Chiropractic | E2: 1883 Station Pkwy NW | G2: Andover | H2: Anoka | I2: Twin Cities Metro | J2: 55304 | K2: (763) 323-0061 | L2: 1 | M2: No | N2: 45559 | O2: Health and Healing Family Chiropractic | P2: 1366657280 | Q2: Map | R2: Record
A3: Moore Therapies, PLLC | B3: Physical Therapy | D3: Physical Therapy | E3: 16817 Zion St NW | G3: Andover | H3: Anoka | I3: Twin Cities Metro | J3: 55304 | K3: (651) 955-3327 | L3: 0 | M3: No | N3: 45408 | O3: Moore Therapies, PLLC | P3: 1225884661 | Q3: Map | R3: Record
A4: 7th Avenue Chiropractic | B4: Chiropractic | D4: Chiropractic | E4: 3722 7th Ave | G4: Anoka | H4: Anoka | I4: Twin Cities Metro | J4: 55303 | K4: (763) 312-1257 | L4: 2 | M4: No | N4: 45659 | O4: 7th Avenue Chiropractic | P4: 1053120220 | Q4: Map | R4: Record
A5: HealthPartners Riverway Pain Clinic | B5: Injury Physicians | D5: Pain Management | E5: 2621 Greenhaven Rd | G5: Anoka | H5: Anoka | I5: Twin Cities Metro | J5: 55303 | K5: (763) 587-4488 | L5: 0 | M5: No | N5: 46240 | O5: Group Health, INC. | P5: 1689068462 | Q5: Map | R5: Record
A6: Kuss Chiropractic | B6: Chiropractic | D6: Chiropractic | E6: 440 Bunker Lake Blvd NW | F6: Ste 105 | G6: Anoka | H6: Anoka | I6: Twin Cities Metro | J6: 55303 | K6: (763) 330-0393 | L6: 1 | M6: No | N6: 45778 | O6: Kuss Company LLC | P6: 1821895756 | Q6: Map | R6: Record
A7: Unison Chiropractic Center PLLC | B7: Chiropractic | D7: Chiropractic | E7: 2006 1st Ave | F7: Ste 209 | G7: Anoka | H7: Anoka | I7: Twin Cities Metro | J7: 55303 | K7: (763) 421-0436 | L7: 1 | M7: No | N7: 46001 | O7: Unison Chiropractic Center PLLC | P7: 1538644885 | Q7: Map | R7: Record
A8: Blaine Chiropractic Center PA | B8: Chiropractic | D8: Chiropractic | E8: 11919 Central Ave NE | G8: Blaine | H8: Anoka | I8: Twin Cities Metro | J8: 55434 | K8: (763) 757-1660 | L8: 8 | M8: No | N8: 45384 | O8: Blaine Chiropractic Center PA | P8: 1376759589 | Q8: Map | R8: Record
A9: Club West Chiropractic PA | B9: Chiropractic | C9: Physical Therapy | D9: Chiropractic, Physical Therapy | E9: 10950 Club West Pkwy | F9: Ste 190 | G9: Blaine | H9: Anoka | I9: Twin Cities Metro | J9: 55449 | K9: (763) 400-4940 | L9: 3 | M9: No | N9: 45348 | O9: Club West Chiropractic PA | P9: 1427447432 | Q9: Map | R9: Record
A10: Concentra Medical Center | B10: Physical Therapy | D10: Physical Therapy | E10: 10190 Baltimore St NE | F10: Ste 100 | G10: Blaine | H10: Anoka | I10: Twin Cities Metro | J10: 55449 | K10: (763) 780-8264 | L10: 0 | M10: No | N10: 45827 | O10: Occupational Health Centers of Minnesota PC | P10: 1508347964 | Q10: Map | R10: Record
A11: Metro Dentalcare Blaine 10 | B11: Oral Surgery | D11: Oral & Maxillofacial Surgery | E11: 261 County Road 10 NE | F11: Ste 10 | G11: Blaine | H11: Anoka | I11: Twin Cities Metro | J11: 55434 | K11: (763) 786-9644 | L11: 0 | M11: No | N11: 44642 | O11: Family Oral Surgery Specialists, PLC | P11: 1730838186 | Q11: Map | R11: Record
A12: Novacare Rehabilitation | B12: Physical Therapy | D12: Physical Therapy | E12: 11855 Ulysses St NE | F12: Ste 20 | G12: Blaine | H12: Anoka | I12: Twin Cities Metro | J12: 55434 | K12: (763) 767-3140 | L12: 10 | M12: No | N12: 45589 | O12: Novacare Outpatient Rehabilitation East, INC. | P12: 1235950957 | Q12: Map | R12: Record
A13: OMS Specialists | B13: Oral Surgery | D13: Oral & Maxillofacial Surgery | E13: 11855 Ulysses Street NE | F13: 130 | G13: Blaine | H13: Anoka | I13: Twin Cities Metro | J13: 55434 | K13: (763) 757-2220 | L13: 0 | M13: No | N13: 41849 | O13: Oral & Maxillofacial Surgery Specialists, PA | P13: 1467563510 | Q13: Map | R13: Record
A14: Open Heart Chiropractic PA | B14: Chiropractic | D14: Chiropractic | E14: 12265 Central Ave NE | G14: Blaine | H14: Anoka | I14: Twin Cities Metro | J14: 55434 | K14: (763) 757-8511 | L14: 2 | M14: No | N14: 45153 | O14: Open Heart Chiropractic PA | P14: 1811687015 | Q14: Map | R14: Record
A15: Summit Orthopedics, LTD | B15: Injury Physicians | D15: Orthopedics, Sports Medicine | E15: 10230 Baltimore St NE | F15: Ste 300 | G15: Blaine | H15: Anoka | I15: Twin Cities Metro | J15: 55449 | K15: (651) 968-5200 | L15: 2 | M15: Yes | N15: 45818 | O15: Summit Orthopedics, LTD | P15: 1043566045 | Q15: Map | R15: Record
A16: The Facial Pain Center | B16: TMJ Specialists | D16: TMJ Treatment | E16: 4190 108th Ave NE | F16: Ste 130 | G16: Blaine | H16: Anoka | I16: Twin Cities Metro | J16: 55449 | K16: (651) 636-2016 | L16: 0 | M16: No | N16: 46245 | O16: Facial Pain Center PLLC | P16: 1407325830 | Q16: Map | R16: Record
A17: Allina Health Brain and Spine Institute - Coon Rapids | B17: Injury Physicians | D17: Neurosurgery | E17: 11850 Blackfoot St NW | F17: Ste 490 | G17: Coon Rapids | H17: Anoka | I17: Twin Cities Metro | J17: 55433 | K17: (612) 871-7278 | L17: 5 | M17: Yes | N17: 46036 | O17: Allina Health System | P17: 1275351413 | Q17: Map | R17: Record
A18: Associated Oral & Maxillofacial Surgeons (Associated OMS) | B18: Oral Surgery | D18: Oral & Maxillofacial Surgery | E18: 3833 Coon Rapids Blvd NW | G18: Coon Rapids | H18: Anoka | I18: Twin Cities Metro | J18: 55433 | K18: (763) 421-6271 | L18: 1 | M18: No | N18: 45441 | O18: MN Dental Service Providers LLC | P18: 1649043662 | Q18: Map | R18: Record
A19: Caring Chiropractic Center, PA. | B19: Chiropractic | D19: Chiropractic | E19: 10811 Xavis St NW | G19: Coon Rapids | H19: Anoka | I19: Twin Cities Metro | J19: 55433 | K19: (763) 421-1905 | L19: 2 | M19: No | N19: 46248 | O19: Caring Chiropractic Center, PA. | P19: 1134494818 | Q19: Map | R19: Record
A20: Concentra Medical Center | B20: Physical Therapy | D20: Physical Therapy | E20: 600 Coon Rapids Blvd NW | F20: Ste 2 | G20: Coon Rapids | H20: Anoka | I20: Twin Cities Metro | J20: 55433 | K20: (651) 968-5273 | L20: 1 | M20: No | N20: 46211 | O20: Occupational Health Centers of Minnesota PC | P20: 1326966300 | Q20: Map | R20: Record
A21: Courage Kenny Rehabilitation Associates | B21: Injury Physicians | D21: Physical Medicine & Rehabilitation | E21: 11850 Blackfoot St NW | F21: Ste 405 | G21: Coon Rapids | H21: Anoka | I21: Twin Cities Metro | J21: 55433 | K21: (763) 236-0888 | L21: 3 | M21: Yes | N21: 45713 | O21: Allina Health System | P21: 1770034670 | Q21: Map | R21: Record
A22: Fit Family Chiropractic | B22: Chiropractic | D22: Chiropractic | E22: 1835 Gateway Dr | F22: Ste 104 | G22: Coon Rapids | H22: Anoka | I22: Twin Cities Metro | J22: 55448 | K22: (763) 710-8888 | L22: 1 | M22: No | N22: 44663 | O22: Moe Chiro Tres PLLC | P22: 1063054302 | Q22: Map | R22: Record
A23: Mary T Outpatient | B23: Physical Therapy | D23: Physical Therapy | E23: 11800 Xeon Blvd NW | G23: Coon Rapids | H23: Anoka | I23: Twin Cities Metro | J23: 55448 | K23: (763) 489-3638 | L23: 4 | M23: No | N23: 44736 | O23: Mary T Outpatient | P23: 1396475927 | Q23: Map | R23: Record
A24: Metropolitan Neurosurgery, PA | B24: Injury Physicians | D24: Neurosurgery | E24: 11850 Blackfoot St NW | F24: Ste 490 | G24: Coon Rapids | H24: Anoka | I24: Twin Cities Metro | J24: 55433 | K24: (763) 427-1137 | L24: 5 | M24: No | N24: 45394 | O24: Metropolitan Neurosurgery, PA | P24: 1386690543 | Q24: Map | R24: Record
A25: Minnesota Neurosurgical Trauma Associates, PLLC | B25: Injury Physicians | D25: Neurosurgery | E25: 11850 Blackfoot St NW | F25: Ste 490 | G25: Coon Rapids | H25: Anoka | I25: Twin Cities Metro | J25: 55433 | K25: (763) 427-1137 | L25: 5 | M25: No | N25: 45407 | O25: Minnesota Neurosurgical Trauma Associates, PLLC | P25: 1922241884 | Q25: Map | R25: Record
A26: Northside Minnesota Oral and Maxillofacial Surgeons, PLLC | B26: Oral Surgery | D26: Oral & Maxillofacial Surgery | E26: 11441 Osage St NW | G26: Coon Rapids | H26: Anoka | I26: Twin Cities Metro | J26: 55433 | K26: (763) 862-6442 | L26: 1 | M26: No | N26: 44369 | O26: Northside Minnesota Oral and Maxillofacial Surgeons, PLLC | P26: 1245809458 | Q26: Map | R26: Record
A27: Novacare Rehabilitation | B27: Physical Therapy | D27: Physical Therapy | E27: 2104 Northdale Blvd NW | F27: Ste 100 | G27: Coon Rapids | H27: Anoka | I27: Twin Cities Metro | J27: 55433 | K27: (763) 755-5495 | L27: 18 | M27: No | N27: 45593 | O27: Novacare Outpatient Rehabilitation East, INC. | P27: 1386466886 | Q27: Map | R27: Record
A28: Novacare Rehabilitation | B28: Physical Therapy | D28: Physical Therapy | E28: 10091 Dogwood St NW | G28: Coon Rapids | H28: Anoka | I28: Twin Cities Metro | J28: 55448 | K28: (763) 450-0298 | L28: 4 | M28: No | N28: 45926 | O28: Novacare Outpatient Rehabilitation East, INC. | P28: 1982246013 | Q28: Map | R28: Record
A29: Pdr Coon Rapids, INC | B29: Injury Physicians | C29: Chiropractic, Physical Therapy | D29: Physical Medicine & Rehabilitation, Chiropractic, Physical Therapy | E29: 320 Coon Rapids Blvd NW | F29: #100 | G29: Coon Rapids | H29: Anoka | I29: Twin Cities Metro | J29: 55433 | K29: (952) 908-2580 | L29: 5 | M29: No | N29: 45911 | O29: Pdr Coon Rapids, INC | P29: 1477666428 | Q29: Map | R29: Record
A30: Restoring Wellness Chiropractic | B30: Chiropractic | D30: Chiropractic | E30: 10811 Xavis St NW | G30: Coon Rapids | H30: Anoka | I30: Twin Cities Metro | J30: 55433 | K30: (763) 285-6475 | L30: 2 | M30: No | N30: 45131 | O30: Restoring Wellness Chiropractic, LLC | P30: 1447934385 | Q30: Map | R30: Record
A31: Summit Orthopedics, LTD. | B31: Physical Therapy | D31: Physical Therapy | E31: 600 Coon Rapids Blvd NW | F31: Ste 150 | G31: Coon Rapids | H31: Anoka | I31: Twin Cities Metro | J31: 55433 | K31: (651) 968-5201 | L31: 1 | M31: No | N31: 45391 | O31: Summit Orthopedics, LTD. | P31: 1770207193 | Q31: Map | R31: Record
A32: The Dental Specialists - Coon Rapids / Riverdale | B32: Oral Surgery | D32: Oral & Maxillofacial Surgery | E32: 3360 Northdale Blvd. | G32: Coon Rapids | H32: Anoka | I32: Twin Cities Metro | J32: 55448 | K32: (763) 233-3390 | L32: 0 | M32: No | N32: 44763 | O32: Dental Specialists of Minnesota, PLLC | P32: 1396095048 | Q32: Map | R32: Record
A33: The Dental Specialists - Coon Rapids Riverdale | B33: Oral Surgery | D33: Oral & Maxillofacial Surgery | E33: 3360 Northdale Blvd NW | G33: Coon Rapids | H33: Anoka | I33: Twin Cities Metro | J33: 55448 | K33: (763) 201-6962 | L33: 0 | M33: No | N33: 44132 | O33: Dental Specialists of Minnesota, PLLC | P33: 1518200286 | Q33: Map | R33: Record
A34: Therapy Partners INC | B34: Physical Therapy | D34: Physical Therapy | E34: 11800 Xeon Blvd NW | G34: Coon Rapids | H34: Anoka | I34: Twin Cities Metro | J34: 55448 | K34: (763) 489-3638 | L34: 4 | M34: No | N34: 45370 | O34: Therapy Partners INC | P34: 1306606397 | Q34: Map | R34: Record
A35: Therapy Partners, INC. | B35: Physical Therapy | D35: Physical Therapy | E35: 8770 Springbrook Dr NW | F35: Ste 100 | G35: Coon Rapids | H35: Anoka | I35: Twin Cities Metro | J35: 55433 | K35: (763) 231-1824 | L35: 6 | M35: No | N35: 46275 | O35: Therapy Partners, INC. | P35: 1407809494 | Q35: Map | R35: Record
A36: Rooted In Wellness Chiropractic LLC | B36: Chiropractic | D36: Chiropractic | E36: 20730 Hamlet Ave N | G36: Forest Lake | H36: Anoka | I36: Twin Cities Metro | J36: 55025 | K36: (651) 248-1841 | L36: 0 | M36: No | N36: 45674 | O36: Rooted In Wellness Chiropractic LLC | P36: 1538970660 | Q36: Map | R36: Record
A37: Heim Chiropractic, PA | B37: Chiropractic | D37: Chiropractic | E37: 7101 Highway 65 NE | F37: Ste 4 | G37: Fridley | H37: Anoka | I37: Twin Cities Metro | J37: 55432 | K37: (651) 482-9160 | L37: 1 | M37: No | N37: 46266 | O37: Heim Chiropractic, PA | P37: 1073675047 | Q37: Map | R37: Record
A38: Minnesota Chiroworks, PLLC | B38: Chiropractic | D38: Chiropractic | E38: 7400 University Ave NE | F38: Ste 100 | G38: Fridley | H38: Anoka | I38: Twin Cities Metro | J38: 55432 | K38: (637) 571-0239 | L38: 0 | M38: No | N38: 44981 | O38: Minnesota Chiroworks, PLLC | P38: 1750917068 | Q38: Map | R38: Record
A39: Novacare Rehabilitation | B39: Physical Therapy | D39: Physical Therapy | E39: 480 Osborne Road | F39: Number 280 | G39: Fridley | H39: Anoka | I39: Twin Cities Metro | J39: 55432 | K39: (763) 784-3155 | L39: 0 | M39: No | N39: 45951 | O39: Novacare Outpatient Rehabilitation East INC | P39: 1558610519 | Q39: Map | R39: Record
A40: Novacare Rehabilitation | B40: Physical Therapy | D40: Physical Therapy | E40: 480 Osborne Rd NE | F40: Ste 280 | G40: Fridley | H40: Anoka | I40: Twin Cities Metro | J40: 55432 | K40: (763) 784-3155 | L40: 3 | M40: No | N40: 45589 | O40: Novacare Outpatient Rehabilitation East, INC. | P40: 1356162051 | Q40: Map | R40: Record
...

Sheet Injury Physicians
A1: Clinic Name | B1: Specialty Group | C1: Also In | D1: Specialties | E1: Street | F1: Suite | G1: City | H1: County | I1: Region | J1: ZIP | K1: Phone | L1: Providers at Address | M1: On Xpert Connect | N1: Registry Updated | O1: Legal Name | P1: NPI | Q1: Map | R1: NPPES Record
A2: HealthPartners Riverway Pain Clinic | B2: Injury Physicians | D2: Pain Management | E2: 2621 Greenhaven Rd | G2: Anoka | H2: Anoka | I2: Twin Cities Metro | J2: 55303 | K2: (763) 587-4488 | L2: 0 | M2: No | N2: 46240 | O2: Group Health, INC. | P2: 1689068462 | Q2: Map | R2: Record
A3: Summit Orthopedics, LTD | B3: Injury Physicians | D3: Orthopedics, Sports Medicine | E3: 10230 Baltimore St NE | F3: Ste 300 | G3: Blaine | H3: Anoka | I3: Twin Cities Metro | J3: 55449 | K3: (651) 968-5200 | L3: 2 | M3: Yes | N3: 45818 | O3: Summit Orthopedics, LTD | P3: 1043566045 | Q3: Map | R3: Record
A4: Allina Health Brain and Spine Institute - Coon Rapids | B4: Injury Physicians | D4: Neurosurgery | E4: 11850 Blackfoot St NW | F4: Ste 490 | G4: Coon Rapids | H4: Anoka | I4: Twin Cities Metro | J4: 55433 | K4: (612) 871-7278 | L4: 5 | M4: Yes | N4: 46036 | O4: Allina Health System | P4: 1275351413 | Q4: Map | R4: Record
A5: Courage Kenny Rehabilitation Associates | B5: Injury Physicians | D5: Physical Medicine & Rehabilitation | E5: 11850 Blackfoot St NW | F5: Ste 405 | G5: Coon Rapids | H5: Anoka | I5: Twin Cities Metro | J5: 55433 | K5: (763) 236-0888 | L5: 3 | M5: Yes | N5: 45713 | O5: Allina Health System | P5: 1770034670 | Q5: Map | R5: Record
A6: Metropolitan Neurosurgery, PA | B6: Injury Physicians | D6: Neurosurgery | E6: 11850 Blackfoot St NW | F6: Ste 490 | G6: Coon Rapids | H6: Anoka | I6: Twin Cities Metro | J6: 55433 | K6: (763) 427-1137 | L6: 5 | M6: No | N6: 45394 | O6: Metropolitan Neurosurgery, PA | P6: 1386690543 | Q6: Map | R6: Record
A7: Minnesota Neurosurgical Trauma Associates, PLLC | B7: Injury Physicians | D7: Neurosurgery | E7: 11850 Blackfoot St NW | F7: Ste 490 | G7: Coon Rapids | H7: Anoka | I7: Twin Cities Metro | J7: 55433 | K7: (763) 427-1137 | L7: 5 | M7: No | N7: 45407 | O7: Minnesota Neurosurgical Trauma Associates, PLLC | P7: 1922241884 | Q7: Map | R7: Record
A8: Pdr Coon Rapids, INC | B8: Injury Physicians | C8: Chiropractic, Physical Therapy | D8: Physical Medicine & Rehabilitation, Chiropractic, Physical Therapy | E8: 320 Coon Rapids Blvd NW | F8: #100 | G8: Coon Rapids | H8: Anoka | I8: Twin Cities Metro | J8: 55433 | K8: (952) 908-2580 | L8: 5 | M8: No | N8: 45911 | O8: Pdr Coon Rapids, INC | P8: 1477666428 | Q8: Map | R8: Record
A9: Nura PLLC | B9: Injury Physicians | D9: Pain Management | E9: 2104 Northdale Boulevard NW | F9: Ste 220 | G9: Minneapolis | H9: Anoka | I9: Twin Cities Metro | J9: 55433 | K9: (763) 537-6000 | L9: 10 | M9: No | N9: 46253 | O9: Nura PLLC | P9: 1750316014 | Q9: Map | R9: Record
A10: Ahc Medical, PC | B10: Injury Physicians | D10: Physical Medicine & Rehabilitation | E10: 1476 White Oak Dr | G10: Chaska | H10: Carver | I10: Twin Cities Metro | J10: 55318 | K10: (952) 448-3900 | L10: 0 | M10: No | N10: 44971 | O10: Ahc Medical, PC | P10: 1336846955 | Q10: Map | R10: Record
A11: Twin Cities Pain Clinic | B11: Injury Physicians | D11: Pain Management, Physical Medicine & Rehabilitation | E11: 584 Bavaria Ln | G11: Chaska | H11: Carver | I11: Twin Cities Metro | J11: 55318 | K11: (952) 841-2345 | L11: 4 | M11: No | N11: 45027 | O11: Andrew J Will MD PA | P11: 1669167920 | Q11: Map | R11: Record
A12: Sage Spine Pain and Nerve Center | B12: Injury Physicians | D12: Pain Management | E12: 38500 Tanger Dr | F12: Ste 110 | G12: North Branch | H12: Chisago | I12: Twin Cities Metro | J12: 55056 | K12: (651) 337-8201 | L12: 1 | M12: No | N12: 46029 | O12: Sage Spine Pain and Nerve Center | P12: 1588536197 | Q12: Map | R12: Record
A13: Fairview Express Care | B13: Injury Physicians | D13: Pain Management | E13: 5200 Fairview Blvd | F13: Ste F | G13: Wyoming | H13: Chisago | I13: Twin Cities Metro | J13: 55092 | K13: (612) 273-5400 | L13: 0 | M13: Yes | N13: 45701 | O13: Fairview Express Care | P13: 1386193613 | Q13: Map | R13: Record
A14: Fairview Express Care | B14: Injury Physicians | D14: Pain Management | E14: 5130 Fairview Blvd | F14: Ste 101 | G14: Wyoming | H14: Chisago | I14: Twin Cities Metro | J14: 55092 | K14: (912) 273-5400 | L14: 0 | M14: Yes | N14: 45701 | O14: Fairview Express Care | P14: 1386193613 | Q14: Map | R14: Record
A15: Inspired Spine Health / Tristate Brain & Spine Institute | B15: Injury Physicians | D15: Orthopedics, Spine | E15: 1601 Highway 13 E | F15: Ste 100 | G15: Burnsville | H15: Dakota | I15: Twin Cities Metro | J15: 55337 | K15: (320) 763-8888 | L15: 2 | M15: Yes | N15: 45176 | O15: Sunny S. Kim, MD PA | P15: 1205481041 | Q15: Map | R15: Record
A16: Pdr Burnsville, INC | B16: Injury Physicians | C16: Chiropractic, Physical Therapy | D16: Physical Medicine & Rehabilitation, Chiropractic, Physical Therapy | E16: 14050 Nicollet Ave | F16: #114 | G16: Burnsville | H16: Dakota | I16: Twin Cities Metro | J16: 55337 | K16: (952) 908-2710 | L16: 1 | M16: No | N16: 45911 | O16: Pdr Burnsville, INC | P16: 1952414971 | Q16: Map | R16: Record
A17: Summit Orthopedics, LTD. | B17: Injury Physicians | D17: Orthopedics | E17: 14101 Fairview Dr | F17: Ste 300 | G17: Burnsville | H17: Dakota | I17: Twin Cities Metro | J17: 55337 | K17: (651) 968-5201 | L17: 2 | M17: Yes | N17: 45978 | O17: Summit Orthopedics, LTD. | P17: 1376403857 | Q17: Map | R17: Record
A18: Sunny S. Kim, MD PA | B18: Injury Physicians | D18: Orthopedics, Spine, Neurosurgery | E18: 1601 Highway 13 E | F18: Ste 100 | G18: Burnsville | H18: Dakota | I18: Twin Cities Metro | J18: 55337 | K18: (320) 763-8888 | L18: 3 | M18: Yes | N18: 46087 | O18: Sunny S. Kim, MD PA | P18: 1659301992 | Q18: Map | R18: Record
A19: Summit Orthopedics, LTD | B19: Injury Physicians | C19: Physical Therapy | D19: Orthopedics, Physical Therapy | E19: 2620 Eagan Woods Dr | G19: Eagan | H19: Dakota | I19: Twin Cities Metro | J19: 55121 | K19: (651) 968-5200 | L19: 23 | M19: Yes | N19: 45867 | O19: Summit Orthopedics, LTD | P19: 1063563518 | Q19: Map | R19: Record
A20: Allina Health Nininger Road Clinic | B20: Injury Physicians | D20: Sports Medicine | E20: 1285 Nininger Rd | G20: Hastings | H20: Dakota | I20: Twin Cities Metro | J20: 55033 | K20: (651) 480-4200 | L20: 0 | M20: No | N20: 46143 | O20: Allina Health System | P20: 1578869293 | Q20: Map | R20: Record
A21: Allina Health Brain and Spine Institute | B21: Injury Physicians | D21: Neurosurgery | E21: 18465 Orchard Trl | G21: Lakeville | H21: Dakota | I21: Twin Cities Metro | J21: 55044 | K21: (800) 827-8313 | L21: 0 | M21: No | N21: 46036 | O21: Allina Health System | P21: 1144264540 | Q21: Map | R21: Record
A22: Allina Health Lakeville Specialty Center | B22: Injury Physicians | D22: Orthopedics | E22: 18465 Orchard Trl | G22: Lakeville | H22: Dakota | I22: Twin Cities Metro | J22: 55044 | K22: (952) 428-0950 | L22: 0 | M22: No | N22: 45671 | O22: Allina Health System | P22: 1003683244 | Q22: Map | R22: Record
A23: Summit Orthopedics, LTD | B23: Injury Physicians | C23: Imaging | D23: Orthopedics, MRI | E23: 17210 Kenyon Ave | G23: Lakeville | H23: Dakota | I23: Twin Cities Metro | J23: 55044 | K23: (651) 968-5201 | L23: 0 | M23: No | N23: 45818 | O23: Summit Orthopedics, LTD | P23: 1629740949 | Q23: Map | R23: Record
A24: Entira Family Clinics-West St. Paul | B24: Injury Physicians | D24: Sports Medicine, Physical Medicine & Rehabilitation | E24: 234 Wentworth Ave E | G24: West St Paul | H24: Dakota | I24: Twin Cities Metro | J24: 55118 | K24: (651) 788-4444 | L24: 0 | M24: No | N24: 45944 | O24: Family Healthservices Minnesota, PA. | P24: 1801076526 | Q24: Map | R24: Record
A25: Infinite Health Collaborative, PA | B25: Injury Physicians | C25: Physical Therapy, Imaging | D25: Orthopedics, Physical Therapy, Radiology | E25: 3500 American Blvd W | F25: Ste 300 | G25: Bloomington | H25: Hennepin | I25: Twin Cities Metro | J25: 55431 | K25: (952) 512-5600 | L25: 0 | M25: Yes | N25: 46177 | O25: Infinite Health Collaborative, PA | P25: 1265675870 | Q25: Map | R25: Record
A26: Ltc Professionals, PLLC | B26: Injury Physicians | D26: Pain Management | E26: 7801 East Bush Lake Rd | F26: Ste 400 | G26: Bloomington | H26: Hennepin | I26: Twin Cities Metro | J26: 55439 | K26: (952) 479-4261 | L26: 0 | M26: No | N26: 45498 | O26: Ltc Professionals, PLLC | P26: 1417251935 | Q26: Map | R26: Record
A27: National Dizzy & Balance Center,ltd. | B27: Injury Physicians | C27: Physical Therapy | D27: Physical Medicine & Rehabilitation, Physical Therapy | E27: 4801 W 81st St | F27: Ste 112 | G27: Bloomington | H27: Hennepin | I27: Twin Cities Metro | J27: 55437 | K27: (952) 345-3000 | L27: 19 | M27: No | N27: 44901 | O27: National Dizzy & Balance Center,ltd. | P27: 1023021938 | Q27: Map | R27: Record
A28: Tria Orthopaedic Center LLC | B28: Injury Physicians | C28: Physical Therapy | D28: Orthopedics, Pain Management, Physical Therapy | E28: 8100 Northland Dr | G28: Bloomington | H28: Hennepin | I28: Twin Cities Metro | J28: 55431 | K28: (952) 831-8742 | L28: 78 | M28: Yes | N28: 46237 | O28: Tria Orthopaedic Center LLC | P28: 1346624384 | Q28: Map | R28: Record
A29: Tria Orthopaedic Clinic | B29: Injury Physicians | C29: Physical Therapy | D29: Orthopedics, Pain Management, Physical Therapy | E29: 8100 Northland Dr | G29: Bloomington | H29: Hennepin | I29: Twin Cities Metro | J29: 55431 | K29: (952) 831-8742 | L29: 78 | M29: Yes | N29: 46237 | O29: Tria Orthopaedic Center LLC | P29: 1518273085 | Q29: Map | R29: Record
A30: Allina Health Orthopedics | B30: Injury Physicians | D30: Orthopedics, Sports Medicine | E30: 6001 96th Ln N | F30: Ste 100 | G30: Brooklyn Park | H30: Hennepin | I30: Twin Cities Metro | J30: 55445 | K30: (952) 946-9777 | L30: 0 | M30: No | N30: 46042 | O30: Allina Health System | P30: 1508099656 | Q30: Map | R30: Record
A31: Team Care Clinic | B31: Chiropractic | C31: Injury Physicians | D31: Sports Medicine, Chiropractic | E31: 12217 Champlin Dr | G31: Champlin | H31: Hennepin | I31: Twin Cities Metro | J31: 55316 | K31: (763) 323-1492 | L31: 5 | M31: No | N31: 44881 | O31: Team Health Care Clinic PC | P31: 1457458689 | Q31: Map | R31: Record
A32: Allina Health Eden Prairie Clinic | B32: Injury Physicians | D32: Orthopedics | E32: 775 Prairie Center Dr | F32: Ste 400 | G32: Eden Prairie | H32: Hennepin | I32: Twin Cities Metro | J32: 55344 | K32: (612) 262-1166 | L32: 1 | M32: Yes | N32: 45716 | O32: Allina Health System | P32: 1699501601 | Q32: Map | R32: Record
A33: Odom Health & Wellness | B33: Injury Physicians | D33: Sports Medicine | E33: 6545 Flying Cloud Dr | F33: Ste 201 | G33: Eden Prairie | H33: Hennepin | I33: Twin Cities Metro | J33: 55344 | K33: (952) 224-1919 | L33: 1 | M33: No | N33: 46141 | O33: Odom Sports Medicine, PA. | P33: 1275557886 | Q33: Map | R33: Record
A34: Summit Orthopedics LTD | B34: Injury Physicians | D34: Orthopedics | E34: 11995 Singletree Ln | F34: Ste 325 | G34: Eden Prairie | H34: Hennepin | I34: Twin Cities Metro | J34: 55344 | K34: (651) 968-5201 | L34: 0 | M34: Yes | N34: 45145 | O34: Summit Orthopedics LTD | P34: 1417639626 | Q34: Map | R34: Record
A35: Allina Health Orthopedics | B35: Injury Physicians | D35: Orthopedics, Sports Medicine | E35: 8100 W 78th St | F35: Ste 230 | G35: Edina | H35: Hennepin | I35: Twin Cities Metro | J35: 55439 | K35: (952) 946-9777 | L35: 43 | M35: Yes | N35: 46042 | O35: Allina Health System | P35: 1508099656 | Q35: Map | R35: Record
A36: Innerwell | B36: Injury Physicians | D36: Pain Management | E36: 5201 Eden Ave | F36: Ste 300 | G36: Edina | H36: Hennepin | I36: Twin Cities Metro | J36: 55436 | K36: (909) 679-3482 | L36: 0 | M36: No | N36: 46128 | O36: Kbs Medical PA | P36: 1295461036 | Q36: Map | R36: Record
A37: Joint Relief Institute | B37: Injury Physicians | D37: Pain Management | E37: 7201 Ohms Ln | F37: Ste 100 | G37: Edina | H37: Hennepin | I37: Twin Cities Metro | J37: 55439 | K37: (708) 726-6694 | L37: 0 | M37: No | N37: 45236 | O37: Karas PLLC | P37: 1811778533 | Q37: Map | R37: Record
A38: Minnesota Neurorehabilitation Institute, PLLC | B38: Injury Physicians | D38: Physical Medicine & Rehabilitation | E38: 7400 Metro Blvd | F38: Ste 400 | G38: Edina | H38: Hennepin | I38: Twin Cities Metro | J38: 55439 | K38: (612) 999-1908 | L38: 1 | M38: No | N38: 45632 | O38: Minnesota Neurorehabilitation Institute, PLLC | P38: 1083253991 | Q38: Map | R38: Record
A39: Minworx Health, LLC | B39: Injury Physicians | D39: Orthopedics | E39: 7505 Metro Blvd | F39: Ste 510 | G39: Edina | H39: Hennepin | I39: Twin Cities Metro | J39: 55439 | K39: (612) 808-9870 | L39: 0 | M39: Yes | N39: 46038 | O39: Minworx Health, LLC | P39: 1225916745 | Q39: Map | R39: Record
A40: Nura PLLC | B40: Injury Physicians | D40: Pain Management | E40: 7400 France Ave S | F40: Ste 100 | G40: Edina | H40: Hennepin | I40: Twin Cities Metro | J40: 55435 | K40: (763) 537-6000 | L40: 8 | M40: No | N40: 46253 | O40: Nura PLLC | P40: 1750316014 | Q40: Map | R40: Record
...

Sheet Chiropractic
A1: Clinic Name | B1: Specialty Group | C1: Also In | D1: Specialties | E1: Street | F1: Suite | G1: City | H1: County | I1: Region | J1: ZIP | K1: Phone | L1: Providers at Address | M1: On Xpert Connect | N1: Registry Updated | O1: Legal Name | P1: NPI | Q1: Map | R1: NPPES Record
A2: Health and Healing Family Chiropractic | B2: Chiropractic | D2: Chiropractic | E2: 1883 Station Pkwy NW | G2: Andover | H2: Anoka | I2: Twin Cities Metro | J2: 55304 | K2: (763) 323-0061 | L2: 1 | M2: No | N2: 45559 | O2: Health and Healing Family Chiropractic | P2: 1366657280 | Q2: Map | R2: Record
A3: 7th Avenue Chiropractic | B3: Chiropractic | D3: Chiropractic | E3: 3722 7th Ave | G3: Anoka | H3: Anoka | I3: Twin Cities Metro | J3: 55303 | K3: (763) 312-1257 | L3: 2 | M3: No | N3: 45659 | O3: 7th Avenue Chiropractic | P3: 1053120220 | Q3: Map | R3: Record
A4: Kuss Chiropractic | B4: Chiropractic | D4: Chiropractic | E4: 440 Bunker Lake Blvd NW | F4: Ste 105 | G4: Anoka | H4: Anoka | I4: Twin Cities Metro | J4: 55303 | K4: (763) 330-0393 | L4: 1 | M4: No | N4: 45778 | O4: Kuss Company LLC | P4: 1821895756 | Q4: Map | R4: Record
A5: Unison Chiropractic Center PLLC | B5: Chiropractic | D5: Chiropractic | E5: 2006 1st Ave | F5: Ste 209 | G5: Anoka | H5: Anoka | I5: Twin Cities Metro | J5: 55303 | K5: (763) 421-0436 | L5: 1 | M5: No | N5: 46001 | O5: Unison Chiropractic Center PLLC | P5: 1538644885 | Q5: Map | R5: Record
A6: Blaine Chiropractic Center PA | B6: Chiropractic | D6: Chiropractic | E6: 11919 Central Ave NE | G6: Blaine | H6: Anoka | I6: Twin Cities Metro | J6: 55434 | K6: (763) 757-1660 | L6: 8 | M6: No | N6: 45384 | O6: Blaine Chiropractic Center PA | P6: 1376759589 | Q6: Map | R6: Record
A7: Club West Chiropractic PA | B7: Chiropractic | C7: Physical Therapy | D7: Chiropractic, Physical Therapy | E7: 10950 Club West Pkwy | F7: Ste 190 | G7: Blaine | H7: Anoka | I7: Twin Cities Metro | J7: 55449 | K7: (763) 400-4940 | L7: 3 | M7: No | N7: 45348 | O7: Club West Chiropractic PA | P7: 1427447432 | Q7: Map | R7: Record
A8: Open Heart Chiropractic PA | B8: Chiropractic | D8: Chiropractic | E8: 12265 Central Ave NE | G8: Blaine | H8: Anoka | I8: Twin Cities Metro | J8: 55434 | K8: (763) 757-8511 | L8: 2 | M8: No | N8: 45153 | O8: Open Heart Chiropractic PA | P8: 1811687015 | Q8: Map | R8: Record
A9: Caring Chiropractic Center, PA. | B9: Chiropractic | D9: Chiropractic | E9: 10811 Xavis St NW | G9: Coon Rapids | H9: Anoka | I9: Twin Cities Metro | J9: 55433 | K9: (763) 421-1905 | L9: 2 | M9: No | N9: 46248 | O9: Caring Chiropractic Center, PA. | P9: 1134494818 | Q9: Map | R9: Record
A10: Fit Family Chiropractic | B10: Chiropractic | D10: Chiropractic | E10: 1835 Gateway Dr | F10: Ste 104 | G10: Coon Rapids | H10: Anoka | I10: Twin Cities Metro | J10: 55448 | K10: (763) 710-8888 | L10: 1 | M10: No | N10: 44663 | O10: Moe Chiro Tres PLLC | P10: 1063054302 | Q10: Map | R10: Record
A11: Pdr Coon Rapids, INC | B11: Injury Physicians | C11: Chiropractic, Physical Therapy | D11: Physical Medicine & Rehabilitation, Chiropractic, Physical Therapy | E11: 320 Coon Rapids Blvd NW | F11: #100 | G11: Coon Rapids | H11: Anoka | I11: Twin Cities Metro | J11: 55433 | K11: (952) 908-2580 | L11: 5 | M11: No | N11: 45911 | O11: Pdr Coon Rapids, INC | P11: 1477666428 | Q11: Map | R11: Record
A12: Restoring Wellness Chiropractic | B12: Chiropractic | D12: Chiropractic | E12: 10811 Xavis St NW | G12: Coon Rapids | H12: Anoka | I12: Twin Cities Metro | J12: 55433 | K12: (763) 285-6475 | L12: 2 | M12: No | N12: 45131 | O12: Restoring Wellness Chiropractic, LLC | P12: 1447934385 | Q12: Map | R12: Record
A13: Rooted In Wellness Chiropractic LLC | B13: Chiropractic | D13: Chiropractic | E13: 20730 Hamlet Ave N | G13: Forest Lake | H13: Anoka | I13: Twin Cities Metro | J13: 55025 | K13: (651) 248-1841 | L13: 0 | M13: No | N13: 45674 | O13: Rooted In Wellness Chiropractic LLC | P13: 1538970660 | Q13: Map | R13: Record
A14: Heim Chiropractic, PA | B14: Chiropractic | D14: Chiropractic | E14: 7101 Highway 65 NE | F14: Ste 4 | G14: Fridley | H14: Anoka | I14: Twin Cities Metro | J14: 55432 | K14: (651) 482-9160 | L14: 1 | M14: No | N14: 46266 | O14: Heim Chiropractic, PA | P14: 1073675047 | Q14: Map | R14: Record
A15: Minnesota Chiroworks, PLLC | B15: Chiropractic | D15: Chiropractic | E15: 7400 University Ave NE | F15: Ste 100 | G15: Fridley | H15: Anoka | I15: Twin Cities Metro | J15: 55432 | K15: (637) 571-0239 | L15: 0 | M15: No | N15: 44981 | O15: Minnesota Chiroworks, PLLC | P15: 1750917068 | Q15: Map | R15: Record
A16: Spinecare Fridley, PC | B16: Chiropractic | D16: Chiropractic | E16: 7872 University Ave NE | G16: Fridley | H16: Anoka | I16: Twin Cities Metro | J16: 55432 | K16: (763) 780-4300 | L16: 3 | M16: No | N16: 44763 | O16: A Plus Chiropractic, PC | P16: 1265953061 | Q16: Map | R16: Record
A17: The Minnesota Chiroworks, PC | B17: Chiropractic | D17: Chiropractic | E17: 7872 University Ave NE | G17: Fridley | H17: Anoka | I17: Twin Cities Metro | J17: 55432 | K17: (763) 780-4300 | L17: 3 | M17: No | N17: 46129 | O17: The Minnesota Chiroworks, PC | P17: 1720874860 | Q17: Map | R17: Record
A18: Exceptional Chiropractic P A | B18: Chiropractic | D18: Chiropractic | E18: 16230 Aberdeen St NE | F18: Ste B | G18: Ham Lake | H18: Anoka | I18: Twin Cities Metro | J18: 55304 | K18: (763) 208-5382 | L18: 2 | M18: No | N18: 45352 | O18: Exceptional Chiropractic P A | P18: 1881795961 | Q18: Map | R18: Record
A19: Exceptional Chiropractic P A | B19: Chiropractic | D19: Chiropractic | E19: 2415 149th Ave NE | G19: Ham Lake | H19: Anoka | I19: Twin Cities Metro | J19: 55304 | K19: (612) 418-3587 | L19: 0 | M19: No | N19: 45352 | O19: Exceptional Chiropractic P A | P19: 1881795961 | Q19: Map | R19: Record
A20: Silver View Chiropractic Center, PA. | B20: Chiropractic | D20: Chiropractic | E20: 4137 Woodland Road | G20: Lexington | H20: Anoka | I20: Twin Cities Metro | J20: 55014 | K20: (763) 786-5581 | L20: 3 | M20: No | N20: 45523 | O20: Silver View Chiropractic Center, PA. | P20: 1740453968 | Q20: Map | R20: Record
A21: Sprout Chiropractic & Wellness | B21: Chiropractic | D21: Chiropractic | E21: 7525 Village Dr | F21: Ste 110 | G21: Lino Lakes | H21: Anoka | I21: Twin Cities Metro | J21: 55014 | K21: (651) 247-0941 | L21: 1 | M21: No | N21: 44760 | O21: Roseville Chiropractic Clinic, LLC | P21: 1699054304 | Q21: Map | R21: Record
A22: Meraki Chiropractic PLLC | B22: Chiropractic | D22: Chiropractic | E22: 19201 Lake George Blvd | F22: Ste C | G22: Oak Grove | H22: Anoka | I22: Twin Cities Metro | J22: 55303 | K22: (763) 200-3370 | L22: 1 | M22: No | N22: 45313 | O22: Meraki Chiropractic PLLC | P22: 1750142360 | Q22: Map | R22: Record
A23: Opp Family Chiropractic PA. | B23: Chiropractic | D23: Chiropractic | E23: 23168 Saint Francis Blvd NW | F23: #600 | G23: St. Francis | H23: Anoka | I23: Twin Cities Metro | J23: 55070 | K23: (763) 213-0615 | L23: 3 | M23: No | N23: 45419 | O23: Opp Family Chiropractic PA. | P23: 1982890810 | Q23: Map | R23: Record
A24: St Lukes Chiropractic | B24: Chiropractic | D24: Chiropractic | E24: 3220 Bridge St NW | F24: Ste 108 | G24: St. Francis | H24: Anoka | I24: Twin Cities Metro | J24: 55070 | K24: (763) 452-0171 | L24: 1 | M24: No | N24: 45260 | O24: St Lukes Chiropractic | P24: 1235715574 | Q24: Map | R24: Record
A25: Backed Chiropractic | B25: Chiropractic | D25: Chiropractic | E25: 1286 Park Rd | F25: # B | G25: Chanhassen | H25: Carver | I25: Twin Cities Metro | J25: 55317 | K25: (952) 451-8571 | L25: 1 | M25: No | N25: 45631 | O25: Backed Chiropractic PLLC | P25: 1720862931 | Q25: Map | R25: Record
A26: Chanhassen Chiropractic | B26: Chiropractic | D26: Chiropractic | E26: 7800 Market Blvd | G26: Chanhassen | H26: Carver | I26: Twin Cities Metro | J26: 55317 | K26: (952) 934-4500 | L26: 2 | M26: No | N26: 45225 | O26: Active Mobility Practitioner PA | P26: 1639528508 | Q26: Map | R26: Record
A27: Discover Chiropractic | B27: Chiropractic | D27: Chiropractic | E27: 1107 Hazeltine Blvd | F27: Ste 100 | G27: Chaska | H27: Carver | I27: Twin Cities Metro | J27: 55318 | K27: (952) 368-4700 | L27: 1 | M27: No | N27: 46246 | O27: Coombs Chiropractic PLLC | P27: 1861317349 | Q27: Map | R27: Record
A28: Lake Life Chiropractic LLC | B28: Chiropractic | D28: Chiropractic | E28: 3650 N Chestnut St | F28: Ste 101A | G28: Chaska | H28: Carver | I28: Twin Cities Metro | J28: 55318 | K28: (612) 562-8384 | L28: 2 | M28: No | N28: 45820 | O28: Lake Life Chiropractic LLC | P28: 1952826778 | Q28: Map | R28: Record
A29: Peak Chiropractic LLC | B29: Chiropractic | D29: Chiropractic | E29: 1107 Hazeltine Blvd | F29: Ste 420 | G29: Chaska | H29: Carver | I29: Twin Cities Metro | J29: 55318 | K29: (952) 600-5584 | L29: 1 | M29: No | N29: 45475 | O29: Peak Chiropractic LLC | P29: 1215773049 | Q29: Map | R29: Record
A30: Sports Performance Chiropractic | B30: Chiropractic | D30: Chiropractic | E30: 350 Highway 7 | F30: Ste 200 | G30: Excelsior | H30: Carver | I30: Twin Cities Metro | J30: 55331 | K30: (952) 529-3905 | L30: 0 | M30: No | N30: 46125 | O30: Sports Performance Chiropractic | P30: 1649113804 | Q30: Map | R30: Record
A31: Power of Life Alternative and Holistic Health | B31: Chiropractic | D31: Chiropractic | E31: 1700 Stieger Lake Ln | F31: Ste 103 | G31: Victoria | H31: Carver | I31: Twin Cities Metro | J31: 55386 | K31: (952) 443-9000 | L31: 1 | M31: No | N31: 45721 | O31: Power of Life Chiropractic, PA. | P31: 1316120272 | Q31: Map | R31: Record
A32: Movewell Chiropractc & Wellness | B32: Chiropractic | D32: Chiropractic | E32: 9360 Oak Ave | G32: Waconia | H32: Carver | I32: Twin Cities Metro | J32: 55387 | K32: (952) 466-6533 | L32: 3 | M32: No | N32: 46230 | O32: Movewell Chiropractc & Wellness | P32: 1972142081 | Q32: Map | R32: Record
A33: Watertown Family Chiropractic | B33: Chiropractic | D33: Chiropractic | E33: 204 Lewis Ave S | F33: Sutie 203 | G33: Watertown | H33: Carver | I33: Twin Cities Metro | J33: 55388 | K33: (515) 320-3841 | L33: 1 | M33: No | N33: 44572 | O33: Ryan Goetz, PA. | P33: 1316185036 | Q33: Map | R33: Record
A34: North Branch Family Chiropractic LLC | B34: Chiropractic | D34: Chiropractic | E34: 6241 Main St | F34: Ste 102 | G34: North Branch | H34: Chisago | I34: Twin Cities Metro | J34: 55056 | K34: (651) 470-5422 | L34: 1 | M34: No | N34: 45751 | O34: North Branch Family Chiropractic LLC | P34: 1437943677 | Q34: Map | R34: Record
A35: Revive Chiropractic | B35: Chiropractic | D35: Chiropractic | E35: 6272 Main St | G35: North Branch | H35: Chisago | I35: Twin Cities Metro | J35: 55056 | K35: (651) 674-2700 | L35: 0 | M35: No | N35: 45090 | O35: Wurdemann Chiropractic PA | P35: 1578850061 | Q35: Map | R35: Record
A36: Weierke Chiropractic PA | B36: Chiropractic | D36: Chiropractic | E36: 386 Bench St | G36: Taylors Falls | H36: Chisago | I36: Twin Cities Metro | J36: 55084 | K36: (651) 465-3811 | L36: 0 | M36: No | N36: 45464 | O36: Weierke Chiropractic PA | P36: 1568876993 | Q36: Map | R36: Record
A37: Apex Family Chiropractic LLC | B37: Chiropractic | D37: Chiropractic | E37: 15678 Pilot Knob Road | F37: Ste 120 | G37: Apple Valley | H37: Dakota | I37: Twin Cities Metro | J37: 55124 | K37: (651) 456-8744 | L37: 1 | M37: No | N37: 44763 | O37: Apex Family Chiropractic LLC | P37: 1982126926 | Q37: Map | R37: Record
A38: Johnson Spinal Care Associates, PA. | B38: Chiropractic | D38: Chiropractic | E38: 14859 Energy Way | G38: Apple Valley | H38: Dakota | I38: Twin Cities Metro | J38: 55124 | K38: (952) 432-3333 | L38: 7 | M38: No | N38: 45005 | O38: Johnson Spinal Care Associates, PA. | P38: 1285711663 | Q38: Map | R38: Record
A39: Lifeway Chiropractic and Wellness LLC | B39: Chiropractic | D39: Chiropractic | E39: 7300 147th St W | F39: Ste 101 | G39: Apple Valley | H39: Dakota | I39: Twin Cities Metro | J39: 55124 | K39: (612) 508-2454 | L39: 6 | M39: No | N39: 45902 | O39: Lifeway Chiropractic and Wellness LLC | P39: 1962568576 | Q39: Map | R39: Record
A40: Bloom Chiropractic Center PA | B40: Chiropractic | D40: Chiropractic | E40: 1606 Cliff Rd E | G40: Burnsville | H40: Dakota | I40: Twin Cities Metro | J40: 55337 | K40: (952) 894-6300 | L40: 1 | M40: No | N40: 44733 | O40: Bloom Chiropractic Center PA | P40: 1417075532 | Q40: Map | R40: Record
...

Sheet Physical Therapy
A1: Clinic Name | B1: Specialty Group | C1: Also In | D1: Specialties | E1: Street | F1: Suite | G1: City | H1: County | I1: Region | J1: ZIP | K1: Phone | L1: Providers at Address | M1: On Xpert Connect | N1: Registry Updated | O1: Legal Name | P1: NPI | Q1: Map | R1: NPPES Record
A2: Moore Therapies, PLLC | B2: Physical Therapy | D2: Physical Therapy | E2: 16817 Zion St NW | G2: Andover | H2: Anoka | I2: Twin Cities Metro | J2: 55304 | K2: (651) 955-3327 | L2: 0 | M2: No | N2: 45408 | O2: Moore Therapies, PLLC | P2: 1225884661 | Q2: Map | R2: Record
A3: Club West Chiropractic PA | B3: Chiropractic | C3: Physical Therapy | D3: Chiropractic, Physical Therapy | E3: 10950 Club West Pkwy | F3: Ste 190 | G3: Blaine | H3: Anoka | I3: Twin Cities Metro | J3: 55449 | K3: (763) 400-4940 | L3: 3 | M3: No | N3: 45348 | O3: Club West Chiropractic PA | P3: 1427447432 | Q3: Map | R3: Record
A4: Concentra Medical Center | B4: Physical Therapy | D4: Physical Therapy | E4: 10190 Baltimore St NE | F4: Ste 100 | G4: Blaine | H4: Anoka | I4: Twin Cities Metro | J4: 55449 | K4: (763) 780-8264 | L4: 0 | M4: No | N4: 45827 | O4: Occupational Health Centers of Minnesota PC | P4: 1508347964 | Q4: Map | R4: Record
A5: Novacare Rehabilitation | B5: Physical Therapy | D5: Physical Therapy | E5: 11855 Ulysses St NE | F5: Ste 20 | G5: Blaine | H5: Anoka | I5: Twin Cities Metro | J5: 55434 | K5: (763) 767-3140 | L5: 10 | M5: No | N5: 45589 | O5: Novacare Outpatient Rehabilitation East, INC. | P5: 1235950957 | Q5: Map | R5: Record
A6: Concentra Medical Center | B6: Physical Therapy | D6: Physical Therapy | E6: 600 Coon Rapids Blvd NW | F6: Ste 2 | G6: Coon Rapids | H6: Anoka | I6: Twin Cities Metro | J6: 55433 | K6: (651) 968-5273 | L6: 1 | M6: No | N6: 46211 | O6: Occupational Health Centers of Minnesota PC | P6: 1326966300 | Q6: Map | R6: Record
A7: Mary T Outpatient | B7: Physical Therapy | D7: Physical Therapy | E7: 11800 Xeon Blvd NW | G7: Coon Rapids | H7: Anoka | I7: Twin Cities Metro | J7: 55448 | K7: (763) 489-3638 | L7: 4 | M7: No | N7: 44736 | O7: Mary T Outpatient | P7: 1396475927 | Q7: Map | R7: Record
A8: Novacare Rehabilitation | B8: Physical Therapy | D8: Physical Therapy | E8: 2104 Northdale Blvd NW | F8: Ste 100 | G8: Coon Rapids | H8: Anoka | I8: Twin Cities Metro | J8: 55433 | K8: (763) 755-5495 | L8: 18 | M8: No | N8: 45593 | O8: Novacare Outpatient Rehabilitation East, INC. | P8: 1386466886 | Q8: Map | R8: Record
A9: Novacare Rehabilitation | B9: Physical Therapy | D9: Physical Therapy | E9: 10091 Dogwood St NW | G9: Coon Rapids | H9: Anoka | I9: Twin Cities Metro | J9: 55448 | K9: (763) 450-0298 | L9: 4 | M9: No | N9: 45926 | O9: Novacare Outpatient Rehabilitation East, INC. | P9: 1982246013 | Q9: Map | R9: Record
A10: Pdr Coon Rapids, INC | B10: Injury Physicians | C10: Chiropractic, Physical Therapy | D10: Physical Medicine & Rehabilitation, Chiropractic, Physical Therapy | E10: 320 Coon Rapids Blvd NW | F10: #100 | G10: Coon Rapids | H10: Anoka | I10: Twin Cities Metro | J10: 55433 | K10: (952) 908-2580 | L10: 5 | M10: No | N10: 45911 | O10: Pdr Coon Rapids, INC | P10: 1477666428 | Q10: Map | R10: Record
A11: Summit Orthopedics, LTD. | B11: Physical Therapy | D11: Physical Therapy | E11: 600 Coon Rapids Blvd NW | F11: Ste 150 | G11: Coon Rapids | H11: Anoka | I11: Twin Cities Metro | J11: 55433 | K11: (651) 968-5201 | L11: 1 | M11: No | N11: 45391 | O11: Summit Orthopedics, LTD. | P11: 1770207193 | Q11: Map | R11: Record
A12: Therapy Partners INC | B12: Physical Therapy | D12: Physical Therapy | E12: 11800 Xeon Blvd NW | G12: Coon Rapids | H12: Anoka | I12: Twin Cities Metro | J12: 55448 | K12: (763) 489-3638 | L12: 4 | M12: No | N12: 45370 | O12: Therapy Partners INC | P12: 1306606397 | Q12: Map | R12: Record
A13: Therapy Partners, INC. | B13: Physical Therapy | D13: Physical Therapy | E13: 8770 Springbrook Dr NW | F13: Ste 100 | G13: Coon Rapids | H13: Anoka | I13: Twin Cities Metro | J13: 55433 | K13: (763) 231-1824 | L13: 6 | M13: No | N13: 46275 | O13: Therapy Partners, INC. | P13: 1407809494 | Q13: Map | R13: Record
A14: Novacare Rehabilitation | B14: Physical Therapy | D14: Physical Therapy | E14: 480 Osborne Road | F14: Number 280 | G14: Fridley | H14: Anoka | I14: Twin Cities Metro | J14: 55432 | K14: (763) 784-3155 | L14: 0 | M14: No | N14: 45951 | O14: Novacare Outpatient Rehabilitation East INC | P14: 1558610519 | Q14: Map | R14: Record
A15: Novacare Rehabilitation | B15: Physical Therapy | D15: Physical Therapy | E15: 480 Osborne Rd NE | F15: Ste 280 | G15: Fridley | H15: Anoka | I15: Twin Cities Metro | J15: 55432 | K15: (763) 784-3155 | L15: 3 | M15: No | N15: 45589 | O15: Novacare Outpatient Rehabilitation East, INC. | P15: 1356162051 | Q15: Map | R15: Record
A16: Hands Hooves and Hearts Therapeutic Services LLC | B16: Physical Therapy | D16: Physical Therapy | E16: 9457 Highway 10 NW | G16: Ramsey | H16: Anoka | I16: Twin Cities Metro | J16: 55303 | K16: (612) 230-0308 | L16: 0 | M16: No | N16: 46107 | O16: Hands Hooves and Hearts Therapeutic Services LLC | P16: 1891332599 | Q16: Map | R16: Record
A17: Kandor Physical Therapy & Pelvic Health LLC | B17: Physical Therapy | D17: Physical Therapy | E17: 8951 Crossroads Blvd | F17: Ste 213 | G17: Chanhassen | H17: Carver | I17: Twin Cities Metro | J17: 55317 | K17: (952) 395-7461 | L17: 0 | M17: No | N17: 46037 | O17: Kandor Physical Therapy & Pelvic Health LLC | P17: 1114885357 | Q17: Map | R17: Record
